Workbook

Sheet TÍNH LÃI LỖ
A1: BẢNG TÍNH CHI PHÍ & LỢI NHUẬN TIKTOK SHOP - HÙNG CƯỜNG
A2: Bản chỉnh: thêm rõ TỔNG CHI PHÍ và tách riêng % hoa hồng Shop thường / % hoa hồng Shop Mall. Người dùng chỉ nhập các ô màu vàng. (BẢNG TẠM TÍNH DỰA TRÊN CÔNG BỐ CỦA TIKTOK)
A4: Tổng doanh thu sau voucher | B4: Tổng chi phí | C4: Tổng lãi ròng | D4: Biên LN TB | E4: Dòng đang lỗ | F4: Tổng phí TikTok | G4: Shop thường | H4: Shop Mall
A5: =SUM(F11:F200) -> 970000 | B5: =SUM(Q11:Q200) -> 851300 | C5: =SUM(R11:R200) -> 118700 | D5: =IFERROR(C5/A5,0) -> 0.12237113 | E5: =COUNTIF(R11:R200,"<0") -> 0 | F5: =SUM(P11:P200) -> 181300 | G5: =COUNTIF(C11:C200,"Marketplace") -> 2 | H5: =COUNTIF(C11:C200,"Mall") -> 1
A7: Cách dùng nhanh: chọn Sản phẩm + Shop, nhập Giá bán, Voucher, Affiliate, Ads, Ship/khác. Xem chi tiết tại sheet HƯỚNG DẪN. Khi đổi Marketplace/Mall, bảng tự đổi % hoa hồng áp dụng.
A9: THÔNG TIN | D9: DOANH THU | G9: CHI PHÍ SHOP NHẬP | K9: PHÍ SÀN / HOA HỒNG TIKTOK | Q9: KẾT QUẢ
A10: Ngày | B10: Sản phẩm | C10: Shop | D10: Giá bán | E10: Voucher shop | F10: Doanh thu sau voucher | G10: CP sản phẩm | H10: Affiliate % | I10: Ads/order | J10: Ship/khác | K10: % HH Shop thường | L10: % HH Shop Mall | M10: Phí HH áp dụng | N10: Phí giao dịch | O10: Phí xử lý | P10: Tổng phí TikTok | Q10: TỔNG CHI PHÍ | R10: Lãi ròng | S10: Biên LN | T10: Cảnh báo | U10: Ghi chú
A11: 46206 | B11: HC001 | Sữa công thức tăng trưởng - mẫu | C11: Marketplace | D11: 450000 | E11: 20000 | F11: =IF($B11="","",$D11-$E11) -> 430000 | G11: =IF($B11="","",IFERROR(INDEX('DATA PHÍ & SẢN PHẨM'!$M$13:$M$200,MATCH($B11,'DATA PHÍ & SẢN PHẨM'!$L$13:$L$200,0)),0)) -> 305000 | H11: 0 | I11: 0 | J11: 0 | K11: =IF($B11="","",IFERROR(INDEX('DATA PHÍ & SẢN PHẨM'!$F$13:$F$200,MATCH($B11,'DATA PHÍ & SẢN PHẨM'!$L$13:$L$200,0)),0)) -> 0.1 | L11: =IF($B11="","",IFERROR(INDEX('DATA PHÍ & SẢN PHẨM'!$G$13:$G$200,MATCH($B11,'DATA PHÍ & SẢN PHẨM'!$L$13:$L$200,0)),0)) -> 0.115 | M11: =IF($B11="","",$F11*IF($C11="Mall",$L11,$K11)) -> 43000 | N11: =IF($B11="","",$F11*'DATA PHÍ & SẢN PHẨM'!$B$4) -> 25800 | O11: =IF($B11="","",'DATA PHÍ & SẢN PHẨM'!$B$5) -> 3000 | P11: =IF($B11="","",SUM(M11:O11)) -> 71800 | Q11: =IF($B11="","",SUM(G11,I11,J11,P11)+($F11*$H11)) -> 376800 | R11: =IF($B11="","",$F11-$Q11) -> 53200 | S11: =IF($B11="","",IFERROR($R11/$F11,0)) -> 0.12372093 | T11: =IF($B11="","",IF($R11<0,"LỖ",IF($S11<0.05,"RẤT NGUY HIỂM",IF($S11<0.1,"LÃI THẤP",IF($S11<0.2,"ỔN","TỐT"))))) -> ỔN | U11: Mẫu sữa tăng trưởng
A12: 46206 | B12: HC003 | Cháo/Bột/Ngũ cốc ăn dặm - mẫu | C12: Marketplace | D12: 250000 | E12: 10000 | F12: =IF($B12="","",$D12-$E12) -> 240000 | G12: =IF($B12="","",IFERROR(INDEX('DATA PHÍ & SẢN PHẨM'!$M$13:$M$200,MATCH($B12,'DATA PHÍ & SẢN PHẨM'!$L$13:$L$200,0)),0)) -> 124000 | H12: 0.05 | I12: 15000 | J12: 0 | K12: =IF($B12="","",IFERROR(INDEX('DATA PHÍ & SẢN PHẨM'!$F$13:$F$200,MATCH($B12,'DATA PHÍ & SẢN PHẨM'!$L$13:$L$200,0)),0)) -> 0.095 | L12: =IF($B12="","",IFERROR(INDEX('DATA PHÍ & SẢN PHẨM'!$G$13:$G$200,MATCH($B12,'DATA PHÍ & SẢN PHẨM'!$L$13:$L$200,0)),0)) -> 0.125 | M12: =IF($B12="","",$F12*IF($C12="Mall",$L12,$K12)) -> 22800 | N12: =IF($B12="","",$F12*'DATA PHÍ & SẢN PHẨM'!$B$4) -> 14400 | O12: =IF($B12="","",'DATA PHÍ & SẢN PHẨM'!$B$5) -> 3000 | P12: =IF($B12="","",SUM(M12:O12)) -> 40200 | Q12: =IF($B12="","",SUM(G12,I12,J12,P12)+($F12*$H12)) -> 191200 | R12: =IF($B12="","",$F12-$Q12) -> 48800 | S12: =IF($B12="","",IFERROR($R12/$F12,0)) -> 0.20333333 | T12: =IF($B12="","",IF($R12<0,"LỖ",IF($S12<0.05,"RẤT NGUY HIỂM",IF($S12<0.1,"LÃI THẤP",IF($S12<0.2,"ỔN","TỐT"))))) -> TỐT | U12: Mẫu có affiliate + ads
A13: 46206 | B13: HC006 | Vitamin & TPBS cho mẹ - mẫu | C13: Mall | D13: 320000 | E13: 20000 | F13: =IF($B13="","",$D13-$E13) -> 300000 | G13: =IF($B13="","",IFERROR(INDEX('DATA PHÍ & SẢN PHẨM'!$M$13:$M$200,MATCH($B13,'DATA PHÍ & SẢN PHẨM'!$L$13:$L$200,0)),0)) -> 165000 | H13: 0.08 | I13: 20000 | J13: 5000 | K13: =IF($B13="","",IFERROR(INDEX('DATA PHÍ & SẢN PHẨM'!$F$13:$F$200,MATCH($B13,'DATA PHÍ & SẢN PHẨM'!$L$13:$L$200,0)),0)) -> 0.135 | L13: =IF($B13="","",IFERROR(INDEX('DATA PHÍ & SẢN PHẨM'!$G$13:$G$200,MATCH($B13,'DATA PHÍ & SẢN PHẨM'!$L$13:$L$200,0)),0)) -> 0.161 | M13: =IF($B13="","",$F13*IF($C13="Mall",$L13,$K13)) -> 48300 | N13: =IF($B13="","",$F13*'DATA PHÍ & SẢN PHẨM'!$B$4) -> 18000 | O13: =IF($B13="","",'DATA PHÍ & SẢN PHẨM'!$B$5) -> 3000 | P13: =IF($B13="","",SUM(M13:O13)) -> 69300 | Q13: =IF($B13="","",SUM(G13,I13,J13,P13)+($F13*$H13)) -> 283300 | R13: =IF($B13="","",$F13-$Q13) -> 16700 | S13: =IF($B13="","",IFERROR($R13/$F13,0)) -> 0.055666667 | T13: =IF($B13="","",IF($R13<0,"LỖ",IF($S13<0.05,"RẤT NGUY HIỂM",IF($S13<0.1,"LÃI THẤP",IF($S13<0.2,"ỔN","TỐT"))))) -> LÃI THẤP | U13: Mẫu Mall
F14: =IF($B14="","",$D14-$E14) | G14: =IF($B14="","",IFERROR(INDEX('DATA PHÍ & SẢN PHẨM'!$M$13:$M$200,MATCH($B14,'DATA PHÍ & SẢN PHẨM'!$L$13:$L$200,0)),0)) | K14: =IF($B14="","",IFERROR(INDEX('DATA PHÍ & SẢN PHẨM'!$F$13:$F$200,MATCH($B14,'DATA PHÍ & SẢN PHẨM'!$L$13:$L$200,0)),0)) | L14: =IF($B14="","",IFERROR(INDEX('DATA PHÍ & SẢN PHẨM'!$G$13:$G$200,MATCH($B14,'DATA PHÍ & SẢN PHẨM'!$L$13:$L$200,0)),0)) | M14: =IF($B14="","",$F14*IF($C14="Mall",$L14,$K14)) | N14: =IF($B14="","",$F14*'DATA PHÍ & SẢN PHẨM'!$B$4) | O14: =IF($B14="","",'DATA PHÍ & SẢN PHẨM'!$B$5) | P14: =IF($B14="","",SUM(M14:O14)) | Q14: =IF($B14="","",SUM(G14,I14,J14,P14)+($F14*$H14)) | R14: =IF($B14="","",$F14-$Q14) | S14: =IF($B14="","",IFERROR($R14/$F14,0)) | T14: =IF($B14="","",IF($R14<0,"LỖ",IF($S14<0.05,"RẤT NGUY HIỂM",IF($S14<0.1,"LÃI THẤP",IF($S14<0.2,"ỔN","TỐT")))))
F15: =IF($B15="","",$D15-$E15) | G15: =IF($B15="","",IFERROR(INDEX('DATA PHÍ & SẢN PHẨM'!$M$13:$M$200,MATCH($B15,'DATA PHÍ & SẢN PHẨM'!$L$13:$L$200,0)),0)) | K15: =IF($B15="","",IFERROR(INDEX('DATA PHÍ & SẢN PHẨM'!$F$13:$F$200,MATCH($B15,'DATA PHÍ & SẢN PHẨM'!$L$13:$L$200,0)),0)) | L15: =IF($B15="","",IFERROR(INDEX('DATA PHÍ & SẢN PHẨM'!$G$13:$G$200,MATCH($B15,'DATA PHÍ & SẢN PHẨM'!$L$13:$L$200,0)),0)) | M15: =IF($B15="","",$F15*IF($C15="Mall",$L15,$K15)) | N15: =IF($B15="","",$F15*'DATA PHÍ & SẢN PHẨM'!$B$4) | O15: =IF($B15="","",'DATA PHÍ & SẢN PHẨM'!$B$5) | P15: =IF($B15="","",SUM(M15:O15)) | Q15: =IF($B15="","",SUM(G15,I15,J15,P15)+($F15*$H15)) | R15: =IF($B15="","",$F15-$Q15) | S15: =IF($B15="","",IFERROR($R15/$F15,0)) | T15: =IF($B15="","",IF($R15<0,"LỖ",IF($S15<0.05,"RẤT NGUY HIỂM",IF($S15<0.1,"LÃI THẤP",IF($S15<0.2,"ỔN","TỐT")))))
F16: =IF($B16="","",$D16-$E16) | G16: =IF($B16="","",IFERROR(INDEX('DATA PHÍ & SẢN PHẨM'!$M$13:$M$200,MATCH($B16,'DATA PHÍ & SẢN PHẨM'!$L$13:$L$200,0)),0)) | K16: =IF($B16="","",IFERROR(INDEX('DATA PHÍ & SẢN PHẨM'!$F$13:$F$200,MATCH($B16,'DATA PHÍ & SẢN PHẨM'!$L$13:$L$200,0)),0)) | L16: =IF($B16="","",IFERROR(INDEX('DATA PHÍ & SẢN PHẨM'!$G$13:$G$200,MATCH($B16,'DATA PHÍ & SẢN PHẨM'!$L$13:$L$200,0)),0)) | M16: =IF($B16="","",$F16*IF($C16="Mall",$L16,$K16)) | N16: =IF($B16="","",$F16*'DATA PHÍ & SẢN PHẨM'!$B$4) | O16: =IF($B16="","",'DATA PHÍ & SẢN PHẨM'!$B$5) | P16: =IF($B16="","",SUM(M16:O16)) | Q16: =IF($B16="","",SUM(G16,I16,J16,P16)+($F16*$H16)) | R16: =IF($B16="","",$F16-$Q16) | S16: =IF($B16="","",IFERROR($R16/$F16,0)) | T16: =IF($B16="","",IF($R16<0,"LỖ",IF($S16<0.05,"RẤT NGUY HIỂM",IF($S16<0.1,"LÃI THẤP",IF($S16<0.2,"ỔN","TỐT")))))
F17: =IF($B17="","",$D17-$E17) | G17: =IF($B17="","",IFERROR(INDEX('DATA PHÍ & SẢN PHẨM'!$M$13:$M$200,MATCH($B17,'DATA PHÍ & SẢN PHẨM'!$L$13:$L$200,0)),0)) | K17: =IF($B17="","",IFERROR(INDEX('DATA PHÍ & SẢN PHẨM'!$F$13:$F$200,MATCH($B17,'DATA PHÍ & SẢN PHẨM'!$L$13:$L$200,0)),0)) | L17: =IF($B17="","",IFERROR(INDEX('DATA PHÍ & SẢN PHẨM'!$G$13:$G$200,MATCH($B17,'DATA PHÍ & SẢN PHẨM'!$L$13:$L$200,0)),0)) | M17: =IF($B17="","",$F17*IF($C17="Mall",$L17,$K17)) | N17: =IF($B17="","",$F17*'DATA PHÍ & SẢN PHẨM'!$B$4) | O17: =IF($B17="","",'DATA PHÍ & SẢN PHẨM'!$B$5) | P17: =IF($B17="","",SUM(M17:O17)) | Q17: =IF($B17="","",SUM(G17,I17,J17,P17)+($F17*$H17)) | R17: =IF($B17="","",$F17-$Q17) | S17: =IF($B17="","",IFERROR($R17/$F17,0)) | T17: =IF($B17="","",IF($R17<0,"LỖ",IF($S17<0.05,"RẤT NGUY HIỂM",IF($S17<0.1,"LÃI THẤP",IF($S17<0.2,"ỔN","TỐT")))))
F18: =IF($B18="","",$D18-$E18) | G18: =IF($B18="","",IFERROR(INDEX('DATA PHÍ & SẢN PHẨM'!$M$13:$M$200,MATCH($B18,'DATA PHÍ & SẢN PHẨM'!$L$13:$L$200,0)),0)) | K18: =IF($B18="","",IFERROR(INDEX('DATA PHÍ & SẢN PHẨM'!$F$13:$F$200,MATCH($B18,'DATA PHÍ & SẢN PHẨM'!$L$13:$L$200,0)),0)) | L18: =IF($B18="","",IFERROR(INDEX('DATA PHÍ & SẢN PHẨM'!$G$13:$G$200,MATCH($B18,'DATA PHÍ & SẢN PHẨM'!$L$13:$L$200,0)),0)) | M18: =IF($B18="","",$F18*IF($C18="Mall",$L18,$K18)) | N18: =IF($B18="","",$F18*'DATA PHÍ & SẢN PHẨM'!$B$4) | O18: =IF($B18="","",'DATA PHÍ & SẢN PHẨM'!$B$5) | P18: =IF($B18="","",SUM(M18:O18)) | Q18: =IF($B18="","",SUM(G18,I18,J18,P18)+($F18*$H18)) | R18: =IF($B18="","",$F18-$Q18) | S18: =IF($B18="","",IFERROR($R18/$F18,0)) | T18: =IF($B18="","",IF($R18<0,"LỖ",IF($S18<0.05,"RẤT NGUY HIỂM",IF($S18<0.1,"LÃI THẤP",IF($S18<0.2,"ỔN","TỐT")))))
F19: =IF($B19="","",$D19-$E19) | G19: =IF($B19="","",IFERROR(INDEX('DATA PHÍ & SẢN PHẨM'!$M$13:$M$200,MATCH($B19,'DATA PHÍ & SẢN PHẨM'!$L$13:$L$200,0)),0)) | K19: =IF($B19="","",IFERROR(INDEX('DATA PHÍ & SẢN PHẨM'!$F$13:$F$200,MATCH($B19,'DATA PHÍ & SẢN PHẨM'!$L$13:$L$200,0)),0)) | L19: =IF($B19="","",IFERROR(INDEX('DATA PHÍ & SẢN PHẨM'!$G$13:$G$200,MATCH($B19,'DATA PHÍ & SẢN PHẨM'!$L$13:$L$200,0)),0)) | M19: =IF($B19="","",$F19*IF($C19="Mall",$L19,$K19)) | N19: =IF($B19="","",$F19*'DATA PHÍ & SẢN PHẨM'!$B$4) | O19: =IF($B19="","",'DATA PHÍ & SẢN PHẨM'!$B$5) | P19: =IF($B19="","",SUM(M19:O19)) | Q19: =IF($B19="","",SUM(G19,I19,J19,P19)+($F19*$H19)) | R19: =IF($B19="","",$F19-$Q19) | S19: =IF($B19="","",IFERROR($R19/$F19,0)) | T19: =IF($B19="","",IF($R19<0,"LỖ",IF($S19<0.05,"RẤT NGUY HIỂM",IF($S19<0.1,"LÃI THẤP",IF($S19<0.2,"ỔN","TỐT")))))
F20: =IF($B20="","",$D20-$E20) | G20: =IF($B20="","",IFERROR(INDEX('DATA PHÍ & SẢN PHẨM'!$M$13:$M$200,MATCH($B20,'DATA PHÍ & SẢN PHẨM'!$L$13:$L$200,0)),0)) | K20: =IF($B20="","",IFERROR(INDEX('DATA PHÍ & SẢN PHẨM'!$F$13:$F$200,MATCH($B20,'DATA PHÍ & SẢN PHẨM'!$L$13:$L$200,0)),0)) | L20: =IF($B20="","",IFERROR(INDEX('DATA PHÍ & SẢN PHẨM'!$G$13:$G$200,MATCH($B20,'DATA PHÍ & SẢN PHẨM'!$L$13:$L$200,0)),0)) | M20: =IF($B20="","",$F20*IF($C20="Mall",$L20,$K20)) | N20: =IF($B20="","",$F20*'DATA PHÍ & SẢN PHẨM'!$B$4) | O20: =IF($B20="","",'DATA PHÍ & SẢN PHẨM'!$B$5) | P20: =IF($B20="","",SUM(M20:O20)) | Q20: =IF($B20="","",SUM(G20,I20,J20,P20)+($F20*$H20)) | R20: =IF($B20="","",$F20-$Q20) | S20: =IF($B20="","",IFERROR($R20/$F20,0)) | T20: =IF($B20="","",IF($R20<0,"LỖ",IF($S20<0.05,"RẤT NGUY HIỂM",IF($S20<0.1,"LÃI THẤP",IF($S20<0.2,"ỔN","TỐT")))))
F21: =IF($B21="","",$D21-$E21) | G21: =IF($B21="","",IFERROR(INDEX('DATA PHÍ & SẢN PHẨM'!$M$13:$M$200,MATCH($B21,'DATA PHÍ & SẢN PHẨM'!$L$13:$L$200,0)),0)) | K21: =IF($B21="","",IFERROR(INDEX('DATA PHÍ & SẢN PHẨM'!$F$13:$F$200,MATCH($B21,'DATA PHÍ & SẢN PHẨM'!$L$13:$L$200,0)),0)) | L21: =IF($B21="","",IFERROR(INDEX('DATA PHÍ & SẢN PHẨM'!$G$13:$G$200,MATCH($B21,'DATA PHÍ & SẢN PHẨM'!$L$13:$L$200,0)),0)) | M21: =IF($B21="","",$F21*IF($C21="Mall",$L21,$K21)) | N21: =IF($B21="","",$F21*'DATA PHÍ & SẢN PHẨM'!$B$4) | O21: =IF($B21="","",'DATA PHÍ & SẢN PHẨM'!$B$5) | P21: =IF($B21="","",SUM(M21:O21)) | Q21: =IF($B21="","",SUM(G21,I21,J21,P21)+($F21*$H21)) | R21: =IF($B21="","",$F21-$Q21) | S21: =IF($B21="","",IFERROR($R21/$F21,0)) | T21: =IF($B21="","",IF($R21<0,"LỖ",IF($S21<0.05,"RẤT NGUY HIỂM",IF($S21<0.1,"LÃI THẤP",IF($S21<0.2,"ỔN","TỐT")))))
F22: =IF($B22="","",$D22-$E22) | G22: =IF($B22="","",IFERROR(INDEX('DATA PHÍ & SẢN PHẨM'!$M$13:$M$200,MATCH($B22,'DATA PHÍ & SẢN PHẨM'!$L$13:$L$200,0)),0)) | K22: =IF($B22="","",IFERROR(INDEX('DATA PHÍ & SẢN PHẨM'!$F$13:$F$200,MATCH($B22,'DATA PHÍ & SẢN PHẨM'!$L$13:$L$200,0)),0)) | L22: =IF($B22="","",IFERROR(INDEX('DATA PHÍ & SẢN PHẨM'!$G$13:$G$200,MATCH($B22,'DATA PHÍ & SẢN PHẨM'!$L$13:$L$200,0)),0)) | M22: =IF($B22="","",$F22*IF($C22="Mall",$L22,$K22)) | N22: =IF($B22="","",$F22*'DATA PHÍ & SẢN PHẨM'!$B$4) | O22: =IF($B22="","",'DATA PHÍ & SẢN PHẨM'!$B$5) | P22: =IF($B22="","",SUM(M22:O22)) | Q22: =IF($B22="","",SUM(G22,I22,J22,P22)+($F22*$H22)) | R22: =IF($B22="","",$F22-$Q22) | S22: =IF($B22="","",IFERROR($R22/$F22,0)) | T22: =IF($B22="","",IF($R22<0,"LỖ",IF($S22<0.05,"RẤT NGUY HIỂM",IF($S22<0.1,"LÃI THẤP",IF($S22<0.2,"ỔN","TỐT")))))
F23: =IF($B23="","",$D23-$E23) | G23: =IF($B23="","",IFERROR(INDEX('DATA PHÍ & SẢN PHẨM'!$M$13:$M$200,MATCH($B23,'DATA PHÍ & SẢN PHẨM'!$L$13:$L$200,0)),0)) | K23: =IF($B23="","",IFERROR(INDEX('DATA PHÍ & SẢN PHẨM'!$F$13:$F$200,MATCH($B23,'DATA PHÍ & SẢN PHẨM'!$L$13:$L$200,0)),0)) | L23: =IF($B23="","",IFERROR(INDEX('DATA PHÍ & SẢN PHẨM'!$G$13:$G$200,MATCH($B23,'DATA PHÍ & SẢN PHẨM'!$L$13:$L$200,0)),0)) | M23: =IF($B23="","",$F23*IF($C23="Mall",$L23,$K23)) | N23: =IF($B23="","",$F23*'DATA PHÍ & SẢN PHẨM'!$B$4) | O23: =IF($B23="","",'DATA PHÍ & SẢN PHẨM'!$B$5) | P23: =IF($B23="","",SUM(M23:O23)) | Q23: =IF($B23="","",SUM(G23,I23,J23,P23)+($F23*$H23)) | R23: =IF($B23="","",$F23-$Q23) | S23: =IF($B23="","",IFERROR($R23/$F23,0)) | T23: =IF($B23="","",IF($R23<0,"LỖ",IF($S23<0.05,"RẤT NGUY HIỂM",IF($S23<0.1,"LÃI THẤP",IF($S23<0.2,"ỔN","TỐT")))))
F24: =IF($B24="","",$D24-$E24) | G24: =IF($B24="","",IFERROR(INDEX('DATA PHÍ & SẢN PHẨM'!$M$13:$M$200,MATCH($B24,'DATA PHÍ & SẢN PHẨM'!$L$13:$L$200,0)),0)) | K24: =IF($B24="","",IFERROR(INDEX('DATA PHÍ & SẢN PHẨM'!$F$13:$F$200,MATCH($B24,'DATA PHÍ & SẢN PHẨM'!$L$13:$L$200,0)),0)) | L24: =IF($B24="","",IFERROR(INDEX('DATA PHÍ & SẢN PHẨM'!$G$13:$G$200,MATCH($B24,'DATA PHÍ & SẢN PHẨM'!$L$13:$L$200,0)),0)) | M24: =IF($B24="","",$F24*IF($C24="Mall",$L24,$K24)) | N24: =IF($B24="","",$F24*'DATA PHÍ & SẢN PHẨM'!$B$4) | O24: =IF($B24="","",'DATA PHÍ & SẢN PHẨM'!$B$5) | P24: =IF($B24="","",SUM(M24:O24)) | Q24: =IF($B24="","",SUM(G24,I24,J24,P24)+($F24*$H24)) | R24: =IF($B24="","",$F24-$Q24) | S24: =IF($B24="","",IFERROR($R24/$F24,0)) | T24: =IF($B24="","",IF($R24<0,"LỖ",IF($S24<0.05,"RẤT NGUY HIỂM",IF($S24<0.1,"LÃI THẤP",IF($S24<0.2,"ỔN","TỐT")))))
F25: =IF($B25="","",$D25-$E25) | G25: =IF($B25="","",IFERROR(INDEX('DATA PHÍ & SẢN PHẨM'!$M$13:$M$200,MATCH($B25,'DATA PHÍ & SẢN PHẨM'!$L$13:$L$200,0)),0)) | K25: =IF($B25="","",IFERROR(INDEX('DATA PHÍ & SẢN PHẨM'!$F$13:$F$200,MATCH($B25,'DATA PHÍ & SẢN PHẨM'!$L$13:$L$200,0)),0)) | L25: =IF($B25="","",IFERROR(INDEX('DATA PHÍ & SẢN PHẨM'!$G$13:$G$200,MATCH($B25,'DATA PHÍ & SẢN PHẨM'!$L$13:$L$200,0)),0)) | M25: =IF($B25="","",$F25*IF($C25="Mall",$L25,$K25)) | N25: =IF($B25="","",$F25*'DATA PHÍ & SẢN PHẨM'!$B$4) | O25: =IF($B25="","",'DATA PHÍ & SẢN PHẨM'!$B$5) | P25: =IF($B25="","",SUM(M25:O25)) | Q25: =IF($B25="","",SUM(G25,I25,J25,P25)+($F25*$H25)) | R25: =IF($B25="","",$F25-$Q25) | S25: =IF($B25="","",IFERROR($R25/$F25,0)) | T25: =IF($B25="","",IF($R25<0,"LỖ",IF($S25<0.05,"RẤT NGUY HIỂM",IF($S25<0.1,"LÃI THẤP",IF($S25<0.2,"ỔN","TỐT")))))
... F200: =IF($B200="","",$D200-$E200) | G200: =IF($B200="","",IFERROR(INDEX('DATA PHÍ & SẢN PHẨM'!$M$13:$M$200,MATCH($B200,'DATA PHÍ & SẢN PHẨM'!$L$13:$L$200,0)),0)) | K200: =IF($B200="","",IFERROR(INDEX('DATA PHÍ & SẢN PHẨM'!$F$13:$F$200,MATCH($B200,'DATA PHÍ & SẢN PHẨM'!$L$13:$L$200,0)),0)) | L200: =IF($B200="","",IFERROR(INDEX('DATA PHÍ & SẢN PHẨM'!$G$13:$G$200,MATCH($B200,'DATA PHÍ & SẢN PHẨM'!$L$13:$L$200,0)),0)) | M200: =IF($B200="","",$F200*IF($C200="Mall",$L200,$K200)) | N200: =IF($B200="","",$F200*'DATA PHÍ & SẢN PHẨM'!$B$4) | O200: =IF($B200="","",'DATA PHÍ & SẢN PHẨM'!$B$5) | P200: =IF($B200="","",SUM(M200:O200)) | Q200: =IF($B200="","",SUM(G200,I200,J200,P200)+($F200*$H200)) | R200: =IF($B200="","",$F200-$Q200) | S200: =IF($B200="","",IFERROR($R200/$F200,0)) | T200: =IF($B200="","",IF($R200<0,"LỖ",IF($S200<0.05,"RẤT NGUY HIỂM",IF($S200<0.1,"LÃI THẤP",IF($S200<0.2,"ỔN","TỐT")))))

Sheet DATA PHÍ & SẢN PHẨM
A1: DATA PHÍ & SẢN PHẨM - TikTok Shop Hùng Cường
A3: Thông số | B3: Giá trị | C3: Ghi chú / Nguồn
A4: Phí giao dịch | B4: 0.06 | C4: PHÍ TIKTOK.docx: Phí giao dịch = 6%
A5: Phí xử lý đơn | B5: 3000 | C5: PHÍ TIKTOK.docx: 3.000đ / đơn giao thành công
A6: Ngày hiệu lực Marketplace | B6: 03/07/2026 | C6: PHÍ NGHÀNH HÀNG.pdf
A7: Ngày hiệu lực Mall | B7: 03/08/2026 | C7: PHÍ NGHÀNH HÀNG.pdf
A8: Lưu ý | B8: Người dùng không cần nhập sheet này | C8: Chỉ sửa khi có SKU/phí/giá vốn thật từ công ty
A9: HƯỚNG DẪN THÊM SKU: thêm sản phẩm từ dòng trống phía dưới, nhập đủ cột A:J, sau đó copy công thức cột L:M từ dòng trên. Dropdown ở sheet TÍNH LÃI LỖ lấy dữ liệu từ L13:L200.
A12: SKU | B12: Tên sản phẩm | C12: Brand | D12: Ngành hàng cấp 3 TikTok | E12: Nhóm nội bộ | F12: % HH Shop thường | G12: % HH Shop Mall | H12: Giá vốn | I12: Đóng gói | J12: Quà tặng | K12: Nguồn / Ghi chú | L12: Sản phẩm chọn | M12: CP sản phẩm mặc định
A13: HC001 | B13: Sữa công thức tăng trưởng - mẫu | C13: Nutricare/Metacare | D13: Sữa công thức tăng trưởng | E13: Sữa & dinh dưỡng | F13: 0.1 | G13: 0.115 | H13: 300000 | I13: 5000 | J13: 0 | K13: PHÍ NGÀNH HÀNG.pdf | L13: =IF(A13="","",A13&" | "&B13) -> HC001 | Sữa công thức tăng trưởng - mẫu | M13: =IF(A13="","",SUM(H13:J13)) -> 305000
A14: HC002 | B14: Sữa công thức sơ sinh - mẫu | C14: Nutricare/Metacare | D14: Sữa công thức sơ sinh | E14: Sữa & dinh dưỡng | F14: 0.095 | G14: 0.105 | H14: 320000 | I14: 5000 | J14: 0 | K14: PHÍ NGÀNH HÀNG.pdf | L14: =IF(A14="","",A14&" | "&B14) -> HC002 | Sữa công thức sơ sinh - mẫu | M14: =IF(A14="","",SUM(H14:J14)) -> 325000
A15: HC003 | B15: Cháo/Bột/Ngũ cốc ăn dặm - mẫu | C15: Nutricare/Metacare | D15: Cháo, Bột & Ngũ cốc | E15: Ăn dặm | F15: 0.095 | G15: 0.125 | H15: 120000 | I15: 4000 | J15: 0 | K15: PHÍ NGÀNH HÀNG.pdf | L15: =IF(A15="","",A15&" | "&B15) -> HC003 | Cháo/Bột/Ngũ cốc ăn dặm - mẫu | M15: =IF(A15="","",SUM(H15:J15)) -> 124000
A16: HC004 | B16: Đồ uống dinh dưỡng - mẫu | C16: Nutricare/Metacare | D16: Đồ uống | E16: Sữa nước/đồ uống | F16: 0.1 | G16: 0.135 | H16: 180000 | I16: 5000 | J16: 0 | K16: PHÍ NGÀNH HÀNG.pdf | L16: =IF(A16="","",A16&" | "&B16) -> HC004 | Đồ uống dinh dưỡng - mẫu | M16: =IF(A16="","",SUM(H16:J16)) -> 185000
A17: HC005 | B17: Sữa cho mẹ bầu / mẹ cho con bú - mẫu | C17: Nutricare/Metacare | D17: Sữa công thức cho phụ nữ mang thai & cho con bú | E17: Mẹ bầu | F17: 0.135 | G17: 0.161 | H17: 280000 | I17: 5000 | J17: 0 | K17: PHÍ NGÀNH HÀNG.pdf | L17: =IF(A17="","",A17&" | "&B17) -> HC005 | Sữa cho mẹ bầu / mẹ cho con bú - mẫu | M17: =IF(A17="","",SUM(H17:J17)) -> 285000
A18: HC006 | B18: Vitamin & TPBS cho mẹ - mẫu | C18: Nutricare/Metacare | D18: Vitamin & Thực phẩm bổ sung cho mẹ | E18: Mẹ bầu | F18: 0.135 | G18: 0.161 | H18: 160000 | I18: 5000 | J18: 0 | K18: PHÍ NGÀNH HÀNG.pdf | L18: =IF(A18="","",A18&" | "&B18) -> HC006 | Vitamin & TPBS cho mẹ - mẫu | M18: =IF(A18="","",SUM(H18:J18)) -> 165000
A19: HC007 | B19: Vitamin & TPBS cho trẻ - mẫu | C19: Nutricare/Metacare | D19: Vitamin & Thực phẩm bổ sung cho trẻ | E19: Bé | F19: 0.13 | G19: 0.16 | H19: 150000 | I19: 5000 | J19: 0 | K19: PHÍ NGÀNH HÀNG.pdf | L19: =IF(A19="","",A19&" | "&B19) -> HC007 | Vitamin & TPBS cho trẻ - mẫu | M19: =IF(A19="","",SUM(H19:J19)) -> 155000
A20: HC008 | B20: Bình sữa & phụ kiện cho bé - mẫu | C20: PUR | D20: Bình sữa & phụ kiện cho bé | E20: Phụ kiện bé | F20: 0.145 | G20: 0.171 | H20: 90000 | I20: 5000 | J20: 0 | K20: PHÍ NGÀNH HÀNG.pdf | L20: =IF(A20="","",A20&" | "&B20) -> HC008 | Bình sữa & phụ kiện cho bé - mẫu | M20: =IF(A20="","",SUM(H20:J20)) -> 95000
A21: HC009 | B21: Máy hút sữa & phụ kiện - mẫu | C21: PUR | D21: Máy hút sữa & phụ kiện | E21: Phụ kiện mẹ | F21: 0.135 | G21: 0.161 | H21: 380000 | I21: 8000 | J21: 0 | K21: PHÍ NGÀNH HÀNG.pdf | L21: =IF(A21="","",A21&" | "&B21) -> HC009 | Máy hút sữa & phụ kiện - mẫu | M21: =IF(A21="","",SUM(H21:J21)) -> 388000
A22: HC010 | B22: Que rửa bình sữa cho bé - mẫu | C22: PUR | D22: Que rửa bình sữa cho bé | E22: Phụ kiện bé | F22: 0.145 | G22: 0.171 | H22: 25000 | I22: 3000 | J22: 0 | K22: PHÍ NGÀNH HÀNG.pdf | L22: =IF(A22="","",A22&" | "&B22) -> HC010 | Que rửa bình sữa cho bé - mẫu | M22: =IF(A22="","",SUM(H22:J22)) -> 28000
A23: HC011 | B23: Yến sào - mẫu | C23: Nunest | D23: Yến sào | E23: Yến sào | F23: 0.125 | G23: 0.157 | H23: 180000 | I23: 5000 | J23: 0 | K23: PHÍ NGÀNH HÀNG.pdf | L23: =IF(A23="","",A23&" | "&B23) -> HC011 | Yến sào - mẫu | M23: =IF(A23="","",SUM(H23:J23)) -> 185000
A24: HC012 | B24: Sữa bột / sản phẩm sữa bột - mẫu | C24: Nutricare/Metacare | D24: Sữa bột | E24: Sữa & dinh dưỡng | F24: 0.11 | G24: 0.14 | H24: 260000 | I24: 5000 | J24: 0 | K24: PHÍ NGÀNH HÀNG.pdf | L24: =IF(A24="","",A24&" | "&B24) -> HC012 | Sữa bột / sản phẩm sữa bột - mẫu | M24: =IF(A24="","",SUM(H24:J24)) -> 265000
L25: =IF(A25="","",A25&" | "&B25) | M25: =IF(A25="","",SUM(H25:J25))
L26: =IF(A26="","",A26&" | "&B26) | M26: =IF(A26="","",SUM(H26:J26))
L27: =IF(A27="","",A27&" | "&B27) | M27: =IF(A27="","",SUM(H27:J27))
L28: =IF(A28="","",A28&" | "&B28) | M28: =IF(A28="","",SUM(H28:J28))
L29: =IF(A29="","",A29&" | "&B29) | M29: =IF(A29="","",SUM(H29:J29))
L30: =IF(A30="","",A30&" | "&B30) | M30: =IF(A30="","",SUM(H30:J30))
L31: =IF(A31="","",A31&" | "&B31) | M31: =IF(A31="","",SUM(H31:J31))
L32: =IF(A32="","",A32&" | "&B32) | M32: =IF(A32="","",SUM(H32:J32))
L33: =IF(A33="","",A33&" | "&B33) | M33: =IF(A33="","",SUM(H33:J33))
L34: =IF(A34="","",A34&" | "&B34) | M34: =IF(A34="","",SUM(H34:J34))
L35: =IF(A35="","",A35&" | "&B35) | M35: =IF(A35="","",SUM(H35:J35))
L36: =IF(A36="","",A36&" | "&B36) | M36: =IF(A36="","",SUM(H36:J36))
... L200: =IF(A200="","",A200&" | "&B200) | M200: =IF(A200="","",SUM(H200:J200))

Sheet HƯỚNG DẪN
A1: HƯỚNG DẪN SỬ DỤNG BẢNG TÍNH CHI PHÍ & LỢI NHUẬN TIKTOK SHOP - HÙNG CƯỜNG
A2: Mục tiêu: giúp nhập nhanh một sản phẩm/đơn hàng và biết ngay doanh thu, tổng phí TikTok, tổng chi phí, lãi/lỗ ròng và biên lợi nhuận.
A4: 1 | B4: Bảng này có những sheet nào?
B5: TÍNH LÃI LỖ | C5: Sheet chính để người dùng nhập dữ liệu và xem kết quả. Đây là sheet dùng hằng ngày.
B6: DATA PHÍ & SẢN PHẨM | C6: Sheet dữ liệu nền: chứa SKU, tên sản phẩm, ngành hàng TikTok, % hoa hồng Shop thường/Mall, giá vốn, đóng gói, quà tặng.
B7: HƯỚNG DẪN | C7: Sheet hướng dẫn cách dùng, cách bảng hoạt động và cách thêm sản phẩm mới.
A9: 2 | B9: Quy ước màu sắc / vùng nhập liệu
B10: Ô màu vàng | C10: Người dùng được nhập/sửa: Ngày, Sản phẩm, Shop, Giá bán, Voucher, Affiliate %, Ads/order, Ship/khác, Ghi chú.
B11: Ô màu xanh / đỏ / kết quả | C11: Không nhập tay. Đây là vùng tự tính: Doanh thu sau voucher, Tổng phí TikTok, Tổng chi phí, Lãi ròng, Biên LN, Cảnh báo.
B12: Sheet DATA | C12: Chỉ sửa khi thêm SKU mới, cập nhật giá vốn hoặc cập nhật % hoa hồng TikTok.
A14: 3 | B14: Cách nhập một dòng tính lãi/lỗ
A15: Bước | B15: Cột trên sheet TÍNH LÃI LỖ | C15: Người dùng làm gì? | D15: Ghi chú
A16: 1 | B16: Ngày | C16: Nhập ngày tính hoặc ngày bán. | D16: Có thể để ngày hiện tại hoặc ngày campaign/live.
A17: 2 | B17: Sản phẩm | C17: Chọn sản phẩm từ danh sách dropdown. | D17: Danh sách này lấy từ cột 'Sản phẩm chọn' trong sheet DATA.
A18: 3 | B18: Shop | C18: Chọn Marketplace hoặc Mall. | D18: Khi đổi Shop, bảng tự đổi % hoa hồng áp dụng.
A19: 4 | B19: Giá bán | C19: Nhập giá bán thực tế trên TikTok. | D19: Nên nhập giá trước khi trừ voucher shop.
A20: 5 | B20: Voucher shop | C20: Nhập số tiền shop tự tài trợ. | D20: Không nhập voucher do TikTok tài trợ nếu công ty không chịu khoản đó.
A21: 6 | B21: Affiliate % | C21: Nhập % hoa hồng creator/KOC nếu có. | D21: Ví dụ 5% thì nhập 5%. Không có thì nhập 0.
A22: 7 | B22: Ads/order | C22: Nhập chi phí quảng cáo phân bổ cho 1 đơn nếu có. | D22: Có thể là TikTok Ads, GMV Max hoặc ads kéo live.
A23: 8 | B23: Ship/khác | C23: Nhập shop hỗ trợ ship, phí phát sinh, claim, phí khác nếu có. | D23: Không có thì để 0.
A24: 9 | B24: Kết quả | C24: Xem Tổng phí TikTok, Tổng chi phí, Lãi ròng, Biên LN, Cảnh báo. | D24: Nếu lãi ròng âm nghĩa là đang lỗ.
A26: 4 | B26: Cách bảng hoạt động / công thức chính
A27: Công thức | B27: Cách tính | C27: Ý nghĩa
A28: Doanh thu sau voucher | B28: Giá bán - Voucher shop | C28: Số doanh thu shop còn lại sau khi tự giảm giá.
A29: % HH áp dụng | B29: Nếu Shop = Mall → dùng % HH Shop Mall; nếu không → dùng % HH Shop thường | C29: Đây là điểm quan trọng nhất khi so sánh Shop thường và Shop Mall.
A30: Phí hoa hồng áp dụng | B30: Doanh thu sau voucher × % HH áp dụng | C30: Phí hoa hồng nền tảng TikTok theo ngành hàng cấp 3.
A31: Phí giao dịch | B31: Doanh thu sau voucher × 6% | C31: Lấy theo cấu hình phí giao dịch trong DATA.
A32: Phí xử lý đơn | B32: 3.000đ / đơn | C32: Lấy theo cấu hình phí xử lý đơn trong DATA.
A33: Tổng phí TikTok | B33: Phí hoa hồng + Phí giao dịch + Phí xử lý đơn | C33: Tổng phí nền tảng TikTok cho đơn đó.
A34: Tổng chi phí | B34: CP sản phẩm + Affiliate tiền + Ads/order + Ship/khác + Tổng phí TikTok | C34: Tổng tiền shop phải chịu cho sản phẩm/đơn đó.
A35: Lãi ròng | B35: Doanh thu sau voucher - Tổng chi phí | C35: Số tiền còn lại sau khi trừ toàn bộ chi phí.
A36: Biên lợi nhuận | B36: Lãi ròng / Doanh thu sau voucher | C36: Cho biết sản phẩm còn khỏe hay không sau khi trừ phí.
A38: 5 | B38: Cách thêm sản phẩm mới vào bảng
A39: Bước | B39: Làm ở đâu? | C39: Cách làm chi tiết | D39: Lưu ý
A40: 1 | B40: DATA PHÍ & SẢN PHẨM | C40: Kéo xuống cuối danh sách SKU hiện có, thêm 1 dòng mới. | D40: Nên thêm từ dòng trống sau các sản phẩm mẫu.
A41: 2 | B41: DATA - cột A | C41: Nhập SKU/mã sản phẩm nội bộ. | D41: Ví dụ HC013, META-OPTI-C, NUNEST-001.
A42: 3 | B42: DATA - cột B | C42: Nhập tên sản phẩm. | D42: Tên này sẽ hiện trong dropdown ở sheet TÍNH LÃI LỖ.
A43: 4 | B43: DATA - cột C:D:E | C43: Nhập Brand, ngành hàng cấp 3 TikTok, nhóm nội bộ. | D43: Ngành hàng cấp 3 dùng để đối chiếu % phí TikTok.
A44: 5 | B44: DATA - cột F:G | C44: Nhập % HH Shop thường và % HH Shop Mall. | D44: Ví dụ 10% và 11.5%. Đây là 2 mức phí khác nhau.
A45: 6 | B45: DATA - cột H:I:J | C45: Nhập Giá vốn, Đóng gói, Quà tặng. | D45: CP sản phẩm mặc định = Giá vốn + Đóng gói + Quà tặng.
...
